Workbook

Sheet LISTA TECNICA
A2: Ref. | B2: Material | C2: Texto breve material | D2: Status | E2: Descrição | F2: LT alt. | G2: TpMaterial | H2: Centro | I2: Material | J2: Texto breve material | K2: Status | L2: Descrição | M2: Qtd.(UMB) | N2: UMB | O2: CONS.Unit | P2: PROGRAMA
P3: =IFERROR(VLOOKUP($A4,'PROGRAMA MES '!$A:$B,2,0),0) -> 2760
A4: =B4 -> 9007 | B4: 9007 | C4: VASSOURA GARI RIGIDA S/CABO SUPERPRO1X12 | D4: 99 | E4: Itens regulares | F4: 1 | G4: VERP | H4: 0800 | I4: 4000138 | J4: AC 944A - 9007 | K4: 99 | L4: Itens regulares | M4: 1667 | N4: PC | O4: =M4/10000 -> 0.1667 | P4: =O4*$P$3 -> 460.092
B5: 9007 | C5: VASSOURA GARI RIGIDA S/CABO SUPERPRO1X12 | D5: 99 | E5: Itens regulares | F5: 1 | G5: VERP | H5: 0800 | I5: 4001340 | J5: CX 944 - 9007 | K5: 99 | L5: Itens regulares | M5: 834 | N5: PC | O5: =M5/10000 -> 0.0834 | P5: =O5*$P$3 -> 230.184
B6: 9007 | C6: VASSOURA GARI RIGIDA S/CABO SUPERPRO1X12 | D6: 99 | E6: Itens regulares | F6: 1 | G6: VERP | H6: 0800 | I6: 4002360 | J6: ETIQ 9007 - PRO | K6: 99 | L6: Itens regulares | M6: 10000 | N6: PC | O6: =M6/10000 -> 1 | P6: =O6*$P$3 -> 2760
B7: 9007 | C7: VASSOURA GARI RIGIDA S/CABO SUPERPRO1X12 | D7: 99 | E7: Itens regulares | F7: 1 | G7: VERP | H7: 0800 | I7: 4002826 | J7: FITA DUREX 70X100MX45MIC C/ IMP. INBETTA | K7: 99 | L7: Itens regulares | M7: 10 | N7: PC | O7: =M7/10000 -> 0.001 | P7: =O7*$P$3 -> 2.76
B8: 9007 | C8: VASSOURA GARI RIGIDA S/CABO SUPERPRO1X12 | D8: 99 | E8: Itens regulares | F8: 1 | G8: FERT | H8: 0800 | I8: C9007 | J8: VASSOURAO GARI CERDAS RIGIDA S/CABO 1X12 | K8: 3 | L8: Itens Inativos | M8: 10000 | N8: PC | O8: =M8/10000 -> 1 | P8: =O8*$P$3 -> 2760
P10: =IFERROR(VLOOKUP($A11,'PROGRAMA MES '!$A:$B,2,0),0) -> 14400
A11: =B11 -> 9010 | B11: 9010 | C11: CABO ACO 1,5M D25MM C/ROSCA SUPERPRO1X12 | D11: 99 | E11: Itens regulares | F11: 1 | G11: VERP | H11: 0800 | I11: 4002366 | J11: ETIQ 9010 CABO CHAPA 1,50 M 25MM - PRO | K11: 99 | L11: Itens regulares | M11: 10000 | N11: PC | O11: =M11/10000 -> 1 | P11: =O11*$P$10 -> 14400
B12: 9010 | C12: CABO ACO 1,5M D25MM C/ROSCA SUPERPRO1X12 | D12: 99 | E12: Itens regulares | F12: 1 | G12: VERP | H12: 0800 | I12: 4012138 | J12: BOB PEBD CANELA TUBULAR 1,8 M X 0,14 MM | K12: 99 | L12: Itens regulares | M12: 44.17 | N12: KG | O12: =M12/10000 -> 0.004417 | P12: =O12*$P$10 -> 63.6048
B13: 9010 | C13: CABO ACO 1,5M D25MM C/ROSCA SUPERPRO1X12 | D13: 99 | E13: Itens regulares | F13: 1 | G13: FERT | H13: 0800 | I13: C9010 | J13: CABO DE CHAPA DE ACO 150CM C/ROSCA 1X12 | K13: 3 | L13: Itens Inativos | M13: 10000 | N13: PC | O13: =M13/10000 -> 1 | P13: =O13*$P$10 -> 14400
P15: =IFERROR(VLOOKUP($A16,'PROGRAMA MES '!$A:$B,2,0),0) -> 1200
A16: =B16 -> 9012 | B16: 9012 | C16: CABO ACO 1,3M D25MM C/ROSCA SUPERPRO1X12 | D16: 99 | E16: Itens regulares | F16: 1 | G16: VERP | H16: 0800 | I16: 4002368 | J16: ETIQ 9012 CABO CHAPA 1,30M 25MM - PRO | K16: 99 | L16: Itens regulares | M16: 10000 | N16: PC | O16: =M16/10000 -> 1 | P16: =O16*$P$15 -> 1200
B17: 9012 | C17: CABO ACO 1,3M D25MM C/ROSCA SUPERPRO1X12 | D17: 99 | E17: Itens regulares | F17: 1 | G17: VERP | H17: 0800 | I17: 4002826 | J17: FITA DUREX 70X100MX45MIC C/ IMP. INBETTA | K17: 99 | L17: Itens regulares | M17: 1 | N17: PC | O17: =M17/10000 -> 0.0001 | P17: =O17*$P$15 -> 0.12
B18: 9012 | C18: CABO ACO 1,3M D25MM C/ROSCA SUPERPRO1X12 | D18: 99 | E18: Itens regulares | F18: 1 | G18: FERT | H18: 0800 | I18: C9012 | J18: CABO CHAPA DE ACO 130CM C/ROSCA 1X12 | K18: 3 | L18: Itens Inativos | M18: 10000 | N18: PC | O18: =M18/10000 -> 1 | P18: =O18*$P$15 -> 1200
P20: =IFERROR(VLOOKUP($A21,'PROGRAMA MES '!$A:$B,2,0),0) -> 0
A21: =B21 -> 9014 | B21: 9014 | C21: CABO ALUMINIO 1,5M D25MM SUPERPRO1X6 | D21: 99 | E21: Itens regulares | F21: 1 | G21: ROH | H21: 0800 | I21: 3005652 | J21: TUBO ALUMINIO 25MMX1500MM | K21: 99 | L21: Itens regulares | M21: 10000 | N21: PC | O21: =M21/10000 -> 1 | P21: =O21*$P$20 -> 0
B22: 9014 | C22: CABO ALUMINIO 1,5M D25MM SUPERPRO1X6 | D22: 99 | E22: Itens regulares | F22: 1 | G22: ROH | H22: 0800 | I22: 3005679 | J22: PUNHO DIAMETRO 25,4 MM - 2000805 | K22: 99 | L22: Itens regulares | M22: 10000 | N22: PC | O22: =M22/10000 -> 1 | P22: =O22*$P$20 -> 0
B23: 9014 | C23: CABO ALUMINIO 1,5M D25MM SUPERPRO1X6 | D23: 99 | E23: Itens regulares | F23: 1 | G23: VERP | H23: 0800 | I23: 4002370 | J23: ETIQ 9014 CABO ALUM 1,50M 25MM - PRO | K23: 99 | L23: Itens regulares | M23: 10000 | N23: PC | O23: =M23/10000 -> 1 | P23: =O23*$P$20 -> 0
B24: 9014 | C24: CABO ALUMINIO 1,5M D25MM SUPERPRO1X6 | D24: 99 | E24: Itens regulares | F24: 1 | G24: VERP | H24: 0800 | I24: 4002826 | J24: FITA DUREX 70X100MX45MIC C/ IMP. INBETTA | K24: 99 | L24: Itens regulares | M24: 20 | N24: PC | O24: =M24/10000 -> 0.002 | P24: =O24*$P$20 -> 0
B25: 9014 | C25: CABO ALUMINIO 1,5M D25MM SUPERPRO1X6 | D25: 99 | E25: Itens regulares | F25: 1 | G25: VERP | H25: 0800 | I25: 4003583 | J25: SACO PEBD 13X170X0,20 P/ CABO ALUMINIO | K25: 99 | L25: Itens regulares | M25: 1667 | N25: PC | O25: =M25/10000 -> 0.1667 | P25: =O25*$P$20 -> 0
B26: 9014 | C26: CABO ALUMINIO 1,5M D25MM SUPERPRO1X6 | D26: 99 | E26: Itens regulares | F26: 1 | G26: VERP | H26: 0800 | I26: 4003593 | J26: SACO PEBD 18X1,70X0,20 CABOS | K26: 99 | L26: Itens regulares | M26: 1667 | N26: PC | O26: =M26/10000 -> 0.1667 | P26: =O26*$P$20 -> 0
P28: =IFERROR(VLOOKUP($A29,'PROGRAMA MES '!$A:$B,2,0),0) -> 3600
A29: =B29 -> 9015 | B29: 9015 | C29: CABO ACO 1,2M D22MM C/ROSCA SUPERPRO1X12 | D29: 99 | E29: Itens regulares | F29: 1 | G29: VERP | H29: 0800 | I29: 4002371 | J29: ETIQ 9015 CABO CHAPA 1,20M 22MM - PRO | K29: 99 | L29: Itens regulares | M29: 10000 | N29: PC | O29: =M29/10000 -> 1 | P29: =O29*$P$28 -> 3600
B30: 9015 | C30: CABO ACO 1,2M D22MM C/ROSCA SUPERPRO1X12 | D30: 99 | E30: Itens regulares | F30: 1 | G30: FERT | H30: 0800 | I30: C9015 | J30: CABO CHAPA DE ACO 120CM C/ROSCA 1X12 | K30: 3 | L30: Itens Inativos | M30: 10000 | N30: PC | O30: =M30/10000 -> 1 | P30: =O30*$P$28 -> 3600
P32: =IFERROR(VLOOKUP($A33,'PROGRAMA MES '!$A:$B,2,0),0) -> 0
A33: =B33 -> 9019 | B33: 9019 | C33: CABO ALUMINIO 1,5M D22MM SUPERPRO1X6 | D33: 99 | E33: Itens regulares | F33: 1 | G33: ROH | H33: 0800 | I33: 3005651 | J33: TUBO DE ALUMINIO 21MM X 1500MM | K33: 99 | L33: Itens regulares | M33: 10000 | N33: PC | O33: =M33/10000 -> 1 | P33: =O33*$P$32 -> 0
B34: 9019 | C34: CABO ALUMINIO 1,5M D22MM SUPERPRO1X6 | D34: 99 | E34: Itens regulares | F34: 1 | G34: ROH | H34: 0800 | I34: 3005680 | J34: PUNHO DIAMETRO 22 MM - 2000804 | K34: 99 | L34: Itens regulares | M34: 10000 | N34: PC | O34: =M34/10000 -> 1 | P34: =O34*$P$32 -> 0
B35: 9019 | C35: CABO ALUMINIO 1,5M D22MM SUPERPRO1X6 | D35: 99 | E35: Itens regulares | F35: 1 | G35: ROH | H35: 0800 | I35: 3005681 | J35: PONTEIRA ROSCA 21-9019 - 2000818 | K35: 99 | L35: Itens regulares | M35: 10000 | N35: PC | O35: =M35/10000 -> 1 | P35: =O35*$P$32 -> 0
B36: 9019 | C36: CABO ALUMINIO 1,5M D22MM SUPERPRO1X6 | D36: 99 | E36: Itens regulares | F36: 1 | G36: VERP | H36: 0800 | I36: 4002373 | J36: ETIQ 9019 - PRO | K36: 99 | L36: Itens regulares | M36: 10000 | N36: PC | O36: =M36/10000 -> 1 | P36: =O36*$P$32 -> 0
B37: 9019 | C37: CABO ALUMINIO 1,5M D22MM SUPERPRO1X6 | D37: 99 | E37: Itens regulares | F37: 1 | G37: VERP | H37: 0800 | I37: 4003583 | J37: SACO PEBD 13X170X0,20 P/ CABO ALUMINIO | K37: 99 | L37: Itens regulares | M37: 1667 | N37: PC | O37: =M37/10000 -> 0.1667 | P37: =O37*$P$32 -> 0
B38: 9019 | C38: CABO ALUMINIO 1,5M D22MM SUPERPRO1X6 | D38: 99 | E38: Itens regulares | F38: 1 | G38: VERP | H38: 0800 | I38: 4003593 | J38: SACO PEBD 18X1,70X0,20 CABOS | K38: 99 | L38: Itens regulares | M38: 1667 | N38: PC | O38: =M38/10000 -> 0.1667 | P38: =O38*$P$32 -> 0
P40: =IFERROR(VLOOKUP($A41,'PROGRAMA MES '!$A:$B,2,0),0) -> 2400
A41: =B41 -> 9032 | B41: 9032 | C41: CABO EXTENSOR ACO 2M SUPERPRO1X6 | D41: 99 | E41: Itens regulares | F41: 1 | G41: VERP | H41: 0800 | I41: 4002378 | J41: ETIQ 9032 - PRO | K41: 99 | L41: Itens regulares | M41: 10000 | N41: PC | O41: =M41/10000 -> 1 | P41: =O41*$P$40 -> 2400
B42: 9032 | C42: CABO EXTENSOR ACO 2M SUPERPRO1X6 | D42: 99 | E42: Itens regulares | F42: 1 | G42: VERP | H42: 0800 | I42: 4002826 | J42: FITA DUREX 70X100MX45MIC C/ IMP. INBETTA | K42: 99 | L42: Itens regulares | M42: 20 | N42: PC | O42: =M42/10000 -> 0.002 | P42: =O42*$P$40 -> 4.8
B43: 9032 | C43: CABO EXTENSOR ACO 2M SUPERPRO1X6 | D43: 99 | E43: Itens regulares | F43: 1 | G43: VERP | H43: 0800 | I43: 4007196 | J43: SACO PEBD 18 X 120 X 0,20 | K43: 99 | L43: Itens regulares | M43: 1667 | N43: PC | O43: =M43/10000 -> 0.1667 | P43: =O43*$P$40 -> 400.08
B44: 9032 | C44: CABO EXTENSOR ACO 2M SUPERPRO1X6 | D44: 99 | E44: Itens regulares | F44: 1 | G44: FERT | H44: 0800 | I44: C9032 | J44: CABO EXTENSOR CHAPA ACO 2 METROS 1X6 | K44: 3 | L44: Itens Inativos | M44: 10000 | N44: PC | O44: =M44/10000 -> 1 | P44: =O44*$P$40 -> 2400
P46: =IFERROR(VLOOKUP($A47,'PROGRAMA MES '!$A:$B,2,0),0) -> 3600
A47: =B47 -> 9033 | B47: 9033 | C47: CABO EXTENSOR ACO 3M SUPERPRO 1X6 | D47: 99 | E47: Itens regulares | F47: 1 | G47: VERP | H47: 0800 | I47: 4002379 | J47: ETIQ 9033 - PRO | K47: 99 | L47: Itens regulares | M47: 10000 | N47: PC | O47: =M47/10000 -> 1 | P47: =O47*$P$46 -> 3600
B48: 9033 | C48: CABO EXTENSOR ACO 3M SUPERPRO 1X6 | D48: 99 | E48: Itens regulares | F48: 1 | G48: VERP | H48: 0800 | I48: 4002826 | J48: FITA DUREX 70X100MX45MIC C/ IMP. INBETTA | K48: 99 | L48: Itens regulares | M48: 20 | N48: PC | O48: =M48/10000 -> 0.002 | P48: =O48*$P$46 -> 7.2
...

Sheet PROGRAMA MES 
A1: REF | B1: PROGR
B2: PÇS
A4: SP9409BA | B4: 20000
A5: 9500 | B5: 200000
A6: SP9500BA | B6: 17400
A7: SP950010BA | B7: 2400
A8: SP9500/1 | B8: 16000
A9: 9502 | B9: 310000
A10: SP9502BA | B10: 4500
A11: SP9502/3 | B11: 0
A12: SP9502BA/2 | B12: 30000
A13: SP9502/2EX | B13: 0
A14: SP950204 | B14: 0
A15: 9504 | B15: 220000
A16: SP9504BA | B16: 100
A17: SP9504BA/2 | B17: 5000
A18: SP950404 | B18: 22000
A19: 9505 | B19: 0
A20: 9506 | B20: 650000
A21: SP9506BA | B21: 6000
A22: SP9506/2 | B22: 5000
A23: SP9506BA/2 | B23: 3000
A24: SP950604 | B24: 0
A25: 9508 | B25: 20000
A26: 9509 | B26: 70000
A27: SP9509/3 | B27: 6400
A28: SP950904 | B28: 0
A29: 9513 | B29: 10000
A30: 9521 | B30: 440000
A31: 9522FR | B31: 264000
A32: SP9522FRBA | B32: 3000
A33: 9522FRBA/2 | B33: 1680
A34: SP9523FR | B34: 156000
A35: SP9524 | B35: 0
A36: SP9526FR | B36: 156000
A37: SP9527 | B37: 20000
A38: SP96170 | B38: 38000
A39: SP98170 | B39: 25800
A40: SP99170 | B40: 4000
A41: SP110170 | B41: 21200
...

Sheet STATUS
A2: DEPOSITO ALMOXARIFADO SUPERPRO | L2: DEPOSITO ALMOX E PRODUÇÃO BETTANIN
A4: CAIXA | L4: ACESSÓRIOS
A5: Material | B5: Descrição do Material | C5: Necessidade programa | D5: 802 | E5: COMPRA | F5: REQUISIÇÃO | G5: PEDIDO | H5: QUANTIDADE | I5: DATA | J5: STATUS | L5: Material | M5: Descrição do Material | N5: Necessidade programa | O5: 805 | P5: 806 | Q5: TOTAL | R5: COMPRA | S5: REQUISIÇÃO | T5: PEDIDO | U5: QUANTIDADE | V5: DATA | W5: STATUS
A6: 4001165 | B6: CX 810 - 9224 | C6: =SUMIF('LISTA TECNICA'!$I:$I,$A6,'LISTA TECNICA'!$P:$P) -> 0 | D6: =IFERROR(VLOOKUP($A6,'0802'!$A:$D,4,0),0) -> 219 | E6: =D6-C6 -> 219 | L6: 4000013 | M6: AC 103C - 888/878 | N6: =SUMIF('LISTA TECNICA'!$I:$I,$L6,'LISTA TECNICA'!$P:$P) -> 200.04 | O6: =IFERROR(VLOOKUP($L6,'0805'!$A:$D,4,0),0) -> 542 | P6: =IFERROR(VLOOKUP($L6,'0806'!$A:$D,4,0),0) -> 0 | Q6: =P6+O6 -> 542 | R6: =Q6-N6 -> 341.96
A7: 4008830 | B7: CX 9157​ | C7: =SUMIF('LISTA TECNICA'!$I:$I,$A7,'LISTA TECNICA'!$P:$P) -> 379.3866 | D7: =IFERROR(VLOOKUP($A7,'0802'!$A:$D,4,0),0) -> 424 | E7: =D7-C7 -> 44.6134 | G7: 4505327845/00020 - 4505399014/00060 | H7: 50- 500 | I7: 14.07.2026 - 17.08.2026 | L7: 4000018 | M7: AC 113 C - I - SUPERPRO KB | N7: =SUMIF('LISTA TECNICA'!$I:$I,$L7,'LISTA TECNICA'!$P:$P) -> 700.35 | O7: =IFERROR(VLOOKUP($L7,'0805'!$A:$D,4,0),0) -> 1760 | P7: =IFERROR(VLOOKUP($L7,'0806'!$A:$D,4,0),0) -> 596 | Q7: =P7+O7 -> 2356 | R7: =Q7-N7 -> 1655.65
A8: 4008832 | B8: CX 9158​ | C8: =SUMIF('LISTA TECNICA'!$I:$I,$A8,'LISTA TECNICA'!$P:$P) -> 504.1008 | D8: =IFERROR(VLOOKUP($A8,'0802'!$A:$D,4,0),0) -> 635 | E8: =D8-C8 -> 130.8992 | G8: 4505399014/00070 | H8: 600 | I8: 17.08.2026 | L8: 4000017 | M8: AC 113A - L - SUPERPRO | N8: =SUMIF('LISTA TECNICA'!$I:$I,$L8,'LISTA TECNICA'!$P:$P) -> 1400.7 | O8: =IFERROR(VLOOKUP($L8,'0805'!$A:$D,4,0),0) -> 1066 | P8: =IFERROR(VLOOKUP($L8,'0806'!$A:$D,4,0),0) -> 2354 | Q8: =P8+O8 -> 3420 | R8: =Q8-N8 -> 2019.3
A9: 4001356 | B9: CX 951 - 9057 | C9: =SUMIF('LISTA TECNICA'!$I:$I,$A9,'LISTA TECNICA'!$P:$P) -> 700.14 | D9: =IFERROR(VLOOKUP($A9,'0802'!$A:$D,4,0),0) -> 1192 | E9: =D9-C9 -> 491.86 | L9: 4008312 | M9: AC 137C NOVO - 9140 | N9: =SUMIF('LISTA TECNICA'!$I:$I,$L9,'LISTA TECNICA'!$P:$P) -> 200.16 | O9: =IFERROR(VLOOKUP($L9,'0805'!$A:$D,4,0),0) -> 1050 | P9: =IFERROR(VLOOKUP($L9,'0806'!$A:$D,4,0),0) -> 0 | Q9: =P9+O9 -> 1050 | R9: =Q9-N9 -> 849.84
A10: 4001360 | B10: CX 952 - 9058 | C10: =SUMIF('LISTA TECNICA'!$I:$I,$A10,'LISTA TECNICA'!$P:$P) -> 0 | D10: =IFERROR(VLOOKUP($A10,'0802'!$A:$D,4,0),0) -> 560 | E10: =D10-C10 -> 560 | L10: 4000056 | M10: AC 216A - 8501 | N10: =SUMIF('LISTA TECNICA'!$I:$I,$L10,'LISTA TECNICA'!$P:$P) -> 199.2 | O10: =IFERROR(VLOOKUP($L10,'0805'!$A:$D,4,0),0) -> 1372 | P10: =IFERROR(VLOOKUP($L10,'0806'!$A:$D,4,0),0) -> 13 | Q10: =P10+O10 -> 1385 | R10: =Q10-N10 -> 1185.8
A11: 4005240 | B11: CX 9700 | C11: =SUMIF('LISTA TECNICA'!$I:$I,$A11,'LISTA TECNICA'!$P:$P) -> 527.1054 | D11: =IFERROR(VLOOKUP($A11,'0802'!$A:$D,4,0),0) -> 685 | E11: =D11-C11 -> 157.8946 | G11: 4505289458/00010 | H11: 60 | I11: 22.06.2026 | L11: 4000056 | M11: AC 216A - 8501 | N11: =SUMIF('LISTA TECNICA'!$I:$I,$L11,'LISTA TECNICA'!$P:$P) -> 199.2 | O11: =IFERROR(VLOOKUP($L11,'0805'!$A:$D,4,0),0) -> 1372 | P11: =IFERROR(VLOOKUP($L11,'0806'!$A:$D,4,0),0) -> 13 | Q11: =P11+O11 -> 1385 | R11: =Q11-N11 -> 1185.8
A12: 4005241 | B12: CX 9701 | C12: =SUMIF('LISTA TECNICA'!$I:$I,$A12,'LISTA TECNICA'!$P:$P) -> 600.12 | D12: =IFERROR(VLOOKUP($A12,'0802'!$A:$D,4,0),0) -> 1269 | E12: =D12-C12 -> 668.88 | L12: 4000070 | M12: AC 24A - 150 | N12: =SUMIF('LISTA TECNICA'!$I:$I,$L12,'LISTA TECNICA'!$P:$P) -> 1100.88 | O12: =IFERROR(VLOOKUP($L12,'0805'!$A:$D,4,0),0) -> 1738 | P12: =IFERROR(VLOOKUP($L12,'0806'!$A:$D,4,0),0) -> 0 | Q12: =P12+O12 -> 1738 | R12: =Q12-N12 -> 637.12
A13: 4005242 | B13: CX 9702 | C13: =SUMIF('LISTA TECNICA'!$I:$I,$A13,'LISTA TECNICA'!$P:$P) -> 258.258 | D13: =IFERROR(VLOOKUP($A13,'0802'!$A:$D,4,0),0) -> 982 | E13: =D13-C13 -> 723.742 | L13: 4000071 | M13: AC 24B - 150 | N13: =SUMIF('LISTA TECNICA'!$I:$I,$L13,'LISTA TECNICA'!$P:$P) -> 2200.44 | O13: =IFERROR(VLOOKUP($L13,'0805'!$A:$D,4,0),0) -> 4085 | P13: =IFERROR(VLOOKUP($L13,'0806'!$A:$D,4,0),0) -> 0 | Q13: =P13+O13 -> 4085 | R13: =Q13-N13 -> 1884.56
A14: 4005245 | B14: CX 9702R | C14: =SUMIF('LISTA TECNICA'!$I:$I,$A14,'LISTA TECNICA'!$P:$P) -> 0 | D14: =IFERROR(VLOOKUP($A14,'0802'!$A:$D,4,0),0) -> 0 | E14: =D14-C14 -> 0 | L14: 4000117 | M14: AC 61C - 566 | N14: =SUMIF('LISTA TECNICA'!$I:$I,$L14,'LISTA TECNICA'!$P:$P) -> 0 | O14: =IFERROR(VLOOKUP($L14,'0805'!$A:$D,4,0),0) -> 600 | P14: =IFERROR(VLOOKUP($L14,'0806'!$A:$D,4,0),0) -> 0 | Q14: =P14+O14 -> 600 | R14: =Q14-N14 -> 600
A15: 4005244 | B15: CX 9704 | C15: =SUMIF('LISTA TECNICA'!$I:$I,$A15,'LISTA TECNICA'!$P:$P) -> 0 | D15: =IFERROR(VLOOKUP($A15,'0802'!$A:$D,4,0),0) -> 0 | E15: =D15-C15 -> 0 | L15: 4000120 | M15: AC 78A - 127040 | N15: =SUMIF('LISTA TECNICA'!$I:$I,$L15,'LISTA TECNICA'!$P:$P) -> 400.08 | O15: =IFERROR(VLOOKUP($L15,'0805'!$A:$D,4,0),0) -> 866 | P15: =IFERROR(VLOOKUP($L15,'0806'!$A:$D,4,0),0) -> 118 | Q15: =P15+O15 -> 984 | R15: =Q15-N15 -> 583.92
A16: 4001403 | B16: CX 993 - 9050 | C16: =SUMIF('LISTA TECNICA'!$I:$I,$A16,'LISTA TECNICA'!$P:$P) -> 600.12 | D16: =IFERROR(VLOOKUP($A16,'0802'!$A:$D,4,0),0) -> 118 | E16: =D16-C16 -> -482.12 | G16: 4505399014/00050 | H16: 500 | I16: 14.08.2026 | L16: 4000121 | M16: AC 793A - 9063/9064 | N16: =SUMIF('LISTA TECNICA'!$I:$I,$L16,'LISTA TECNICA'!$P:$P) -> 950.76 | O16: =IFERROR(VLOOKUP($L16,'0805'!$A:$D,4,0),0) -> 2122 | P16: =IFERROR(VLOOKUP($L16,'0806'!$A:$D,4,0),0) -> 27 | Q16: =P16+O16 -> 2149 | R16: =Q16-N16 -> 1198.24
A17: 4001404 | B17: CX 994 - 9056 | C17: =SUMIF('LISTA TECNICA'!$I:$I,$A17,'LISTA TECNICA'!$P:$P) -> 0 | D17: =IFERROR(VLOOKUP($A17,'0802'!$A:$D,4,0),0) -> 950 | E17: =D17-C17 -> 950 | L17: 4000124 | M17: AC 84A - 118040 | N17: =SUMIF('LISTA TECNICA'!$I:$I,$L17,'LISTA TECNICA'!$P:$P) -> 400.32 | O17: =IFERROR(VLOOKUP($L17,'0805'!$A:$D,4,0),0) -> 700 | P17: =IFERROR(VLOOKUP($L17,'0806'!$A:$D,4,0),0) -> 0 | Q17: =P17+O17 -> 700 | R17: =Q17-N17 -> 299.68
A18: 4011430 | B18: CX MASTER SP9740 | C18: =SUMIF('LISTA TECNICA'!$I:$I,$A18,'LISTA TECNICA'!$P:$P) -> 0 | D18: =IFERROR(VLOOKUP($A18,'0802'!$A:$D,4,0),0) -> 0 | E18: =D18-C18 -> 0 | L18: 4000125 | M18: AC 84D - 1182 | N18: =SUMIF('LISTA TECNICA'!$I:$I,$L18,'LISTA TECNICA'!$P:$P) -> 800.16 | O18: =IFERROR(VLOOKUP($L18,'0805'!$A:$D,4,0),0) -> 871 | P18: =IFERROR(VLOOKUP($L18,'0806'!$A:$D,4,0),0) -> 401 | Q18: =P18+O18 -> 1272 | R18: =Q18-N18 -> 471.84
A19: 4011431 | B19: CX MASTER SP9742 | C19: =SUMIF('LISTA TECNICA'!$I:$I,$A19,'LISTA TECNICA'!$P:$P) -> 0 | D19: =IFERROR(VLOOKUP($A19,'0802'!$A:$D,4,0),0) -> 0 | E19: =D19-C19 -> 0 | L19: 4016880 | M19: AC 860A | N19: =SUMIF('LISTA TECNICA'!$I:$I,$L19,'LISTA TECNICA'!$P:$P) -> 2700 | O19: =IFERROR(VLOOKUP($L19,'0805'!$A:$D,4,0),0) -> 0 | P19: =IFERROR(VLOOKUP($L19,'0806'!$A:$D,4,0),0) -> 1608 | Q19: =P19+O19 -> 1608 | R19: =Q19-N19 -> -1092 | T19: 4505337207/00050 | U19: 2500 | V19: 30.07.2026
A20: 4011432 | B20: CX MASTER SP9743 | C20: =SUMIF('LISTA TECNICA'!$I:$I,$A20,'LISTA TECNICA'!$P:$P) -> 0 | D20: =IFERROR(VLOOKUP($A20,'0802'!$A:$D,4,0),0) -> 0 | E20: =D20-C20 -> 0 | L20: 4000126 | M20: AC 868A -98812EX/9021 | N20: =SUMIF('LISTA TECNICA'!$I:$I,$L20,'LISTA TECNICA'!$P:$P) -> 0 | O20: =IFERROR(VLOOKUP($L20,'0805'!$A:$D,4,0),0) -> 375 | P20: =IFERROR(VLOOKUP($L20,'0806'!$A:$D,4,0),0) -> 0 | Q20: =P20+O20 -> 375 | R20: =Q20-N20 -> 375
A21: 4011433 | B21: CX MASTER SP9744 | C21: =SUMIF('LISTA TECNICA'!$I:$I,$A21,'LISTA TECNICA'!$P:$P) -> 0 | D21: =IFERROR(VLOOKUP($A21,'0802'!$A:$D,4,0),0) -> 0 | E21: =D21-C21 -> 0 | L21: 4000129 | M21: AC 870A - 9004D | N21: =SUMIF('LISTA TECNICA'!$I:$I,$L21,'LISTA TECNICA'!$P:$P) -> 650.52 | O21: =IFERROR(VLOOKUP($L21,'0805'!$A:$D,4,0),0) -> 1840 | P21: =IFERROR(VLOOKUP($L21,'0806'!$A:$D,4,0),0) -> 612 | Q21: =P21+O21 -> 2452 | R21: =Q21-N21 -> 1801.48
A22: 4016923 | B22: CX SP12000100 | C22: =SUMIF('LISTA TECNICA'!$I:$I,$A22,'LISTA TECNICA'!$P:$P) -> 0 | D22: =IFERROR(VLOOKUP($A22,'0802'!$A:$D,4,0),0) -> 0 | E22: =D22-C22 -> 0 | L22: 4008733 | M22: AC 875 CAN - 9053C | N22: =SUMIF('LISTA TECNICA'!$I:$I,$L22,'LISTA TECNICA'!$P:$P) -> 400.2 | O22: =IFERROR(VLOOKUP($L22,'0805'!$A:$D,4,0),0) -> 600 | P22: =IFERROR(VLOOKUP($L22,'0806'!$A:$D,4,0),0) -> 0 | Q22: =P22+O22 -> 600 | R22: =Q22-N22 -> 199.8
A23: 4007480 | B23: CX SP303530 | C23: =SUMIF('LISTA TECNICA'!$I:$I,$A23,'LISTA TECNICA'!$P:$P) -> 475.38 | D23: =IFERROR(VLOOKUP($A23,'0802'!$A:$D,4,0),0) -> 1290 | E23: =D23-C23 -> 814.62 | L23: 4008732 | M23: AC 875 TAB - 9053C | N23: =SUMIF('LISTA TECNICA'!$I:$I,$L23,'LISTA TECNICA'!$P:$P) -> 200.1 | O23: =IFERROR(VLOOKUP($L23,'0805'!$A:$D,4,0),0) -> 757 | P23: =IFERROR(VLOOKUP($L23,'0806'!$A:$D,4,0),0) -> 0 | Q23: =P23+O23 -> 757 | R23: =Q23-N23 -> 556.9
A24: 4004700 | B24: CX SP304530 - 824 | C24: =SUMIF('LISTA TECNICA'!$I:$I,$A24,'LISTA TECNICA'!$P:$P) -> 100.08 | D24: =IFERROR(VLOOKUP($A24,'0802'!$A:$D,4,0),0) -> 438 | E24: =D24-C24 -> 337.92 | L24: 4011811 | M24: AC 9070D - A | N24: =SUMIF('LISTA TECNICA'!$I:$I,$L24,'LISTA TECNICA'!$P:$P) -> 0 | O24: =IFERROR(VLOOKUP($L24,'0805'!$A:$D,4,0),0) -> 238 | P24: =IFERROR(VLOOKUP($L24,'0806'!$A:$D,4,0),0) -> 0 | Q24: =P24+O24 -> 238 | R24: =Q24-N24 -> 238
A25: 4010424 | B25: CX SP9232 | C25: =SUMIF('LISTA TECNICA'!$I:$I,$A25,'LISTA TECNICA'!$P:$P) -> 0 | D25: =IFERROR(VLOOKUP($A25,'0802'!$A:$D,4,0),0) -> 708 | E25: =D25-C25 -> 708 | L25: 4011815 | M25: AC 9070D - B | N25: =SUMIF('LISTA TECNICA'!$I:$I,$L25,'LISTA TECNICA'!$P:$P) -> 0 | O25: =IFERROR(VLOOKUP($L25,'0805'!$A:$D,4,0),0) -> 700 | P25: =IFERROR(VLOOKUP($L25,'0806'!$A:$D,4,0),0) -> 0 | Q25: =P25+O25 -> 700 | R25: =Q25-N25 -> 700
A26: 4010426 | B26: CX SP9232/1 | C26: =SUMIF('LISTA TECNICA'!$I:$I,$A26,'LISTA TECNICA'!$P:$P) -> 0 | D26: =IFERROR(VLOOKUP($A26,'0802'!$A:$D,4,0),0) -> 0 | E26: =D26-C26 -> 0 | L26: 4000133 | M26: AC 911A - 9145 | N26: =SUMIF('LISTA TECNICA'!$I:$I,$L26,'LISTA TECNICA'!$P:$P) -> 500.4 | O26: =IFERROR(VLOOKUP($L26,'0805'!$A:$D,4,0),0) -> 1039 | P26: =IFERROR(VLOOKUP($L26,'0806'!$A:$D,4,0),0) -> 6 | Q26: =P26+O26 -> 1045 | R26: =Q26-N26 -> 544.6
A27: 4005290 | B27: CX SP9709 | C27: =SUMIF('LISTA TECNICA'!$I:$I,$A27,'LISTA TECNICA'!$P:$P) -> 0 | D27: =IFERROR(VLOOKUP($A27,'0802'!$A:$D,4,0),0) -> 0 | E27: =D27-C27 -> 0 | L27: 4012869 | M27: AC 911B - 9145 | N27: =SUMIF('LISTA TECNICA'!$I:$I,$L27,'LISTA TECNICA'!$P:$P) -> 2000.4 | O27: =IFERROR(VLOOKUP($L27,'0805'!$A:$D,4,0),0) -> 3280 | P27: =IFERROR(VLOOKUP($L27,'0806'!$A:$D,4,0),0) -> 24 | Q27: =P27+O27 -> 3304 | R27: =Q27-N27 -> 1303.6
A28: 4011434 | B28: CX SP9740 PAPEL HIGIENICO | C28: =SUMIF('LISTA TECNICA'!$I:$I,$A28,'LISTA TECNICA'!$P:$P) -> 0 | D28: =IFERROR(VLOOKUP($A28,'0802'!$A:$D,4,0),0) -> 0 | E28: =D28-C28 -> 0 | L28: 4008731 | M28: AC 9154/9054C CAN | N28: =SUMIF('LISTA TECNICA'!$I:$I,$L28,'LISTA TECNICA'!$P:$P) -> 800.4 | O28: =IFERROR(VLOOKUP($L28,'0805'!$A:$D,4,0),0) -> 1940 | P28: =IFERROR(VLOOKUP($L28,'0806'!$A:$D,4,0),0) -> 0 | Q28: =P28+O28 -> 1940 | R28: =Q28-N28 -> 1139.6
A29: 4001359 | B29: AC SP9347/SP9348 190X240MM | C29: =SUMIF('LISTA TECNICA'!$I:$I,$A29,'LISTA TECNICA'!$P:$P) -> 1200.24 | D29: =IFERROR(VLOOKUP($A29,'0802'!$A:$D,4,0),0) -> 1562 | E29: =D29-C29 -> 361.76 | L29: 4008730 | M29: AC 9154/9054C TAB | N29: =SUMIF('LISTA TECNICA'!$I:$I,$L29,'LISTA TECNICA'!$P:$P) -> 400.2 | O29: =IFERROR(VLOOKUP($L29,'0805'!$A:$D,4,0),0) -> 1247 | P29: =IFERROR(VLOOKUP($L29,'0806'!$A:$D,4,0),0) -> 0 | Q29: =P29+O29 -> 1247 | R29: =Q29-N29 -> 846.8
A30: 4016811 | B30: ACESSORIO 720X350MM | C30: =SUMIF('LISTA TECNICA'!$I:$I,$A30,'LISTA TECNICA'!$P:$P) -> 400.08 | D30: =IFERROR(VLOOKUP($A30,'0802'!$A:$D,4,0),0) -> 2440 | E30: =D30-C30 -> 2039.92 | L30: 4006456 | M30: AC 9260 - 851/1 | N30: =SUMIF('LISTA TECNICA'!$I:$I,$L30,'LISTA TECNICA'!$P:$P) -> 1200.96 | O30: =IFERROR(VLOOKUP($L30,'0805'!$A:$D,4,0),0) -> 2164 | P30: =IFERROR(VLOOKUP($L30,'0806'!$A:$D,4,0),0) -> 172 | Q30: =P30+O30 -> 2336 | R30: =Q30-N30 -> 1135.04
A31: 4011435 | B31: CX SP9742 SANONETE LIQ | C31: =SUMIF('LISTA TECNICA'!$I:$I,$A31,'LISTA TECNICA'!$P:$P) -> 0 | D31: =IFERROR(VLOOKUP($A31,'0802'!$A:$D,4,0),0) -> 0 | E31: =D31-C31 -> 0 | L31: 4007347 | M31: AC 9260 - 851/2 | N31: =SUMIF('LISTA TECNICA'!$I:$I,$L31,'LISTA TECNICA'!$P:$P) -> 2400.48 | O31: =IFERROR(VLOOKUP($L31,'0805'!$A:$D,4,0),0) -> 1880 | P31: =IFERROR(VLOOKUP($L31,'0806'!$A:$D,4,0),0) -> 0 | Q31: =P31+O31 -> 1880 | R31: =Q31-N31 -> -520.48 | T31: 4505398940/00010 | U31: 1500 | V31: 12.08.2026
A32: 4001186 | B32: CX 833 - 90502 | C32: =SUMIF('LISTA TECNICA'!$I:$I,$A32,'LISTA TECNICA'!$P:$P) -> 16.68 | D32: =IFERROR(VLOOKUP($A32,'0802'!$A:$D,4,0),0) -> 0 | E32: =D32-C32 -> -16.68 | L32: 4007348 | M32: AC 9260 - 851/3 | N32: =SUMIF('LISTA TECNICA'!$I:$I,$L32,'LISTA TECNICA'!$P:$P) -> 4800.96 | O32: =IFERROR(VLOOKUP($L32,'0805'!$A:$D,4,0),0) -> 6253 | P32: =IFERROR(VLOOKUP($L32,'0806'!$A:$D,4,0),0) -> 0 | Q32: =P32+O32 -> 6253 | R32: =Q32-N32 -> 1452.04
A33: 4001187 | B33: CX 834 - 90503 | C33: =SUMIF('LISTA TECNICA'!$I:$I,$A33,'LISTA TECNICA'!$P:$P) -> 16.68 | D33: =IFERROR(VLOOKUP($A33,'0802'!$A:$D,4,0),0) -> 0 | E33: =D33-C33 -> -16.68 | L33: 4008674 | M33: AC 9261/1 | N33: =SUMIF('LISTA TECNICA'!$I:$I,$L33,'LISTA TECNICA'!$P:$P) -> 0 | O33: =IFERROR(VLOOKUP($L33,'0805'!$A:$D,4,0),0) -> 659 | P33: =IFERROR(VLOOKUP($L33,'0806'!$A:$D,4,0),0) -> 0 | Q33: =P33+O33 -> 659 | R33: =Q33-N33 -> 659
A34: 4011437 | B34: CX SP9743 PAPEL TOALHA | C34: =SUMIF('LISTA TECNICA'!$I:$I,$A34,'LISTA TECNICA'!$P:$P) -> 0 | D34: =IFERROR(VLOOKUP($A34,'0802'!$A:$D,4,0),0) -> 0 | E34: =D34-C34 -> 0 | L34: 4008676 | M34: AC 9261/2 | N34: =SUMIF('LISTA TECNICA'!$I:$I,$L34,'LISTA TECNICA'!$P:$P) -> 0 | O34: =IFERROR(VLOOKUP($L34,'0805'!$A:$D,4,0),0) -> 300 | P34: =IFERROR(VLOOKUP($L34,'0806'!$A:$D,4,0),0) -> 0 | Q34: =P34+O34 -> 300 | R34: =Q34-N34 -> 300
A35: 4003879 | B35: CX 9102 TELA | C35: =SUMIF('LISTA TECNICA'!$I:$I,$A35,'LISTA TECNICA'!$P:$P) -> 0 | D35: =IFERROR(VLOOKUP($A35,'0802'!$A:$D,4,0),0) -> 0 | E35: =D35-C35 -> 0 | L35: 4014845 | M35: AC 928 - 9142 | N35: =SUMIF('LISTA TECNICA'!$I:$I,$L35,'LISTA TECNICA'!$P:$P) -> 380.304 | O35: =IFERROR(VLOOKUP($L35,'0805'!$A:$D,4,0),0) -> 700 | P35: =IFERROR(VLOOKUP($L35,'0806'!$A:$D,4,0),0) -> 0 | Q35: =P35+O35 -> 700 | R35: =Q35-N35 -> 319.696
A36: 4013822 | B36: CXSP40/2AC | C36: =SUMIF('LISTA TECNICA'!$I:$I,$A36,'LISTA TECNICA'!$P:$P) -> 0 | D36: =IFERROR(VLOOKUP($A36,'0802'!$A:$D,4,0),0) -> 280 | E36: =D36-C36 -> 280 | L36: 4000136 | M36: AC 93A - 1842 | N36: =SUMIF('LISTA TECNICA'!$I:$I,$L36,'LISTA TECNICA'!$P:$P) -> 0 | O36: =IFERROR(VLOOKUP($L36,'0805'!$A:$D,4,0),0) -> 612 | P36: =IFERROR(VLOOKUP($L36,'0806'!$A:$D,4,0),0) -> 0 | Q36: =P36+O36 -> 612 | R36: =Q36-N36 -> 612
L37: 4000137 | M37: AC 93B - 1842 | N37: =SUMIF('LISTA TECNICA'!$I:$I,$L37,'LISTA TECNICA'!$P:$P) -> 0 | O37: =IFERROR(VLOOKUP($L37,'0805'!$A:$D,4,0),0) -> 450 | P37: =IFERROR(VLOOKUP($L37,'0806'!$A:$D,4,0),0) -> 0 | Q37: =P37+O37 -> 450 | R37: =Q37-N37 -> 450
A38: ETIQUETA | L38: 4000138 | M38: AC 944A - 9007 | N38: =SUMIF('LISTA TECNICA'!$I:$I,$L38,'LISTA TECNICA'!$P:$P) -> 460.092 | O38: =IFERROR(VLOOKUP($L38,'0805'!$A:$D,4,0),0) -> 800 | P38: =IFERROR(VLOOKUP($L38,'0806'!$A:$D,4,0),0) -> 0 | Q38: =P38+O38 -> 800 | R38: =Q38-N38 -> 339.908
A39: Material | B39: Descrição do Material | C39: Necessidade programa | D39: 802 | E39: COMPRA | F39: REQUISIÇÃO | G39: PEDIDO | H39: QUANTIDADE | I39: DATA | J39: STATUS | L39: 4000141 | M39: AC 953A - 9139 | N39: =SUMIF('LISTA TECNICA'!$I:$I,$L39,'LISTA TECNICA'!$P:$P) -> 964.7712 | O39: =IFERROR(VLOOKUP($L39,'0805'!$A:$D,4,0),0) -> 3966 | P39: =IFERROR(VLOOKUP($L39,'0806'!$A:$D,4,0),0) -> 117 | Q39: =P39+O39 -> 4083 | R39: =Q39-N39 -> 3118.2288
A40: 4009849 | B40: ETIQ HEAT TRANSFER-PLACAS SINALIZADORAS | C40: =SUMIF('LISTA TECNICA'!$I:$I,$A40,'LISTA TECNICA'!$P:$P) -> 2400 | D40: =IFERROR(VLOOKUP($A40,'0802'!$A:$D,4,0),0) -> 5710 | E40: =D40-C40 -> 3310 | L40: 4014389 | M40: AC 9677A | N40: =SUMIF('LISTA TECNICA'!$I:$I,$L40,'LISTA TECNICA'!$P:$P) -> 0 | O40: =IFERROR(VLOOKUP($L40,'0805'!$A:$D,4,0),0) -> 650 | P40: =IFERROR(VLOOKUP($L40,'0806'!$A:$D,4,0),0) -> 0 | Q40: =P40+O40 -> 650 | R40: =Q40-N40 -> 650 | T40: 4505069593/00060 | U40: 400 | V40: 27.03.2026
A41: 4002370 | B41: ETIQ 9014 CABO ALUM 1,50M 25MM - PRO | C41: =SUMIF('LISTA TECNICA'!$I:$I,$A41,'LISTA TECNICA'!$P:$P) -> 0 | D41: =IFERROR(VLOOKUP($A41,'0802'!$A:$D,4,0),0) -> 9400 | E41: =D41-C41 -> 9400 | L41: 4014388 | M41: AC 9677B | N41: =SUMIF('LISTA TECNICA'!$I:$I,$L41,'LISTA TECNICA'!$P:$P) -> 0 | O41: =IFERROR(VLOOKUP($L41,'0805'!$A:$D,4,0),0) -> 1650 | P41: =IFERROR(VLOOKUP($L41,'0806'!$A:$D,4,0),0) -> 0 | Q41: =P41+O41 -> 1650 | R41: =Q41-N41 -> 1650
A42: 4002373 | B42: ETIQ 9019 - PRO | C42: =SUMIF('LISTA TECNICA'!$I:$I,$A42,'LISTA TECNICA'!$P:$P) -> 0 | D42: =IFERROR(VLOOKUP($A42,'0802'!$A:$D,4,0),0) -> 11913 | E42: =D42-C42 -> 11913 | L42: 4005883 | M42: AC LIX 30 | N42: =SUMIF('LISTA TECNICA'!$I:$I,$L42,'LISTA TECNICA'!$P:$P) -> 0 | O42: =IFERROR(VLOOKUP($L42,'0805'!$A:$D,4,0),0) -> 0 | P42: =IFERROR(VLOOKUP($L42,'0806'!$A:$D,4,0),0) -> 0 | Q42: =P42+O42 -> 0 | R42: =Q42-N42 -> 0
...

Sheet 0802
A1: Material | B1: Texto breve material | C1: Depósito | D1: Utilização livre | E1: UMB | F1: Val.utiliz.livre
A2: 107 | B2: NOVICA LIMPA PERSIANAS MICROFIBRA 1X12​ | C2: 0802 | D2: 0 | E2: PC | F2: 0
A3: 108 | B3: NOVICA ESPANADOR MICROFIBRA LONGO 1X6​ | C3: 0802 | D3: 0 | E3: PC | F3: 0
A4: 109 | B4: NOVICA ESPANADOR CURTO MICROFIBRA 1X12​​ | C4: 0802 | D4: 0 | E4: PC | F4: 0
A5: 110 | B5: NOVICA LUVA MAGICA MICROFIBRA 1X6​ | C5: 0802 | D5: 0 | E5: PC | F5: 0
A6: 114 | B6: NOVICA ESCOVA ADAPT PLASTICA 1X36 | C6: 0802 | D6: 0 | E6: PC | F6: 0
A7: 201 | B7: NOVICA ROLO ADESIVO PAPEL 1X24 | C7: 0802 | D7: 0 | E7: PC | F7: 0
A8: 235 | B8: BALDE OVAL PLASTICO SANREMO 14L | C8: 0802 | D8: 0 | E8: PC | F8: 0
A9: 278 | B9: LIXEIRA BASCULANTE PIA PL SANREMO 6,5L | C9: 0802 | D9: 0 | E9: PC | F9: 0
A10: 279 | B10: LIXEIRA BASCULANTE PLASTICO SANREMO 19L | C10: 0802 | D10: 0 | E10: PC | F10: 0
A11: 280 | B11: LIXEIRA BASCULANTE PLAS SANREMO 20,5L | C11: 0802 | D11: 0 | E11: PC | F11: 0
A12: 281 | B12: LIXEIRA BASCULANTE PLASTICO SANREMO 10L | C12: 0802 | D12: 0 | E12: PC | F12: 0
A13: 283 | B13: LIXEIRA BASCULANTE PLASTICO SANREMO 30L | C13: 0802 | D13: 0 | E13: PC | F13: 0
... A2057: 14004057 | B2057: FACA PICOTE 2300X33X2 DESENHO MPP01002 | C2057: 0802 | D2057: 9 | E2057: PC | F2057: 625.51
A2058: 10051E | B2058: DISCO ULTRA REMOVEDOR AZUL 510MM 1X20 | C2058: 0802 | D2058: 0 | E2058: PC | F2058: 0
A2059: 10051S | B2059: DISCO ULTRA REMOV.AZUL ONDA 510MM 1X20 | C2059: 0802 | D2059: 0 | E2059: PC | F2059: 0
A2060: 11041E | B2060: DISCO LUSTRADOR VERMELHO 410MM 1X20 | C2060: 0802 | D2060: 0 | E2060: PC | F2060: 0
A2061: 11044E | B2061: DISCO LUSTRADOR VERMELHO 440MM 1X20 | C2061: 0802 | D2061: 0 | E2061: PC | F2061: 0
A2062: 11051E | B2062: DISCO RESTAURADOR VERMELHO 510MM 1X20 | C2062: 0802 | D2062: 0 | E2062: PC | F2062: 0
A2063: 12044E | B2063: DISCO LUSTRADOR CHAMPAGNE - 1 X 20 | C2063: 0802 | D2063: 0 | E2063: PC | F2063: 0
A2064: 13000/4G | B2064: LUVAS MULTIUSO AM LATEX G SUPERPRO 1X48 | C2064: 0802 | D2064: 18480 | E2064: PC | F2064: 22933.68
A2065: 13000/4M | B2065: LUVAS MULTIUSO AM LATEX M SUPERPRO 1X48 | C2065: 0802 | D2065: 42768 | E2065: PC | F2065: 54122.9
A2066: 13000/4P | B2066: LUVAS MULTIUSO AM LATEX P SUPERPRO 1X48 | C2066: 0802 | D2066: 1488 | E2066: PC | F2066: 1843.63
A2067: 13000AZ/4G | B2067: LUVAS MULTIUSO AZ LATEX G SUPERPRO 1X48 | C2067: 0802 | D2067: 24672 | E2067: PC | F2067: 32552.24
A2068: 13000AZ/4M | B2068: LUVAS MULTIUSO AZ LATEX M SUPERPRO 1X48 | C2068: 0802 | D2068: 43008 | E2068: PC | F2068: 52099.89
A2069: 13000AZ/4P | B2069: LUVAS MULTIUSO AZ LATEX P SUPERPRO 1X48 | C2069: 0802 | D2069: 12672 | E2069: PC | F2069: 15302.71
... A4034: SR64/25 | B4034: LIXEIRA SELETIVA MARROM PL SANREMO 40L | C4034: 0802 | D4034: 0 | E4034: PC | F4034: 0
D4035: 135796.42 | E4035: KG | F4035: 7651401.1
D4036: 0 | E4036: L
D4037: 0 | E4037: M
D4038: 0 | E4038: M2
D4039: 2106306 | E4039: PC
D4040: 0 | E4040: UN

Sheet 0805
A1: Material | B1: Texto breve material | C1: Depósito | D1: Utilização livre | E1: UMB | F1: Val.utiliz.livre
A2: 9256 | B2: LIXEIRA BASCUL. 60L PLAST. SUPERPRO1X6 | C2: 0805 | D2: 0 | E2: PC | F2: 0
A3: 9257 | B3: LIXEIRA BASCUL. 105L PLAST. SUPERPRO 1X6 | C3: 0805 | D3: 0 | E3: PC | F3: 0
A4: 9349 | B4: LIXEIRA COM PEDAL PEQUENA | C4: 0805 | D4: 0 | E4: PC | F4: 0
A5: 9350 | B5: LIXEIRA BASCULANTE MEDIA COM BAGFIX | C5: 0805 | D5: 0 | E5: PC | F5: 0
A6: 9351 | B6: LIXEIRA C/ PEDAL SUPERPRO 13,5L 1X6 | C6: 0805 | D6: 0 | E6: PC | F6: 0
A7: 9352 | B7: LIXEIRA RETA BASCUL.PEQUENA 10L-1X12 | C7: 0805 | D7: 0 | E7: PC | F7: 0
A8: 9353 | B8: LIXEIRA RETA BASC.GRANDE 20,50L -1X4 | C8: 0805 | D8: 0 | E8: PC | F8: 0
A9: 9356 | B9: LIXEIRA PLAST. C/PEDAL 36L SUPERPRO 1X3 | C9: 0805 | D9: 0 | E9: PC | F9: 0
A10: 9357 | B10: LIXEIRA PLAST. C/PEDAL 72L SUPERPRO 1X3 | C10: 0805 | D10: 0 | E10: PC | F10: 0
A11: 2000818 | B11: PONT ROSCA INTERNA D21 MOL089P PRETA | C11: 0805 | D11: 0 | E11: PC | F11: 0
A12: 3000741 | B12: PIG MASTER CINZA ESCURO PCZ1368 | C12: 0805 | D12: 0 | E12: KG | F12: 0
A13: 3001466 | B13: TUBO DE PAPEL 38,0X1,0X300,0MM​ | C13: 0805 | D13: 0 | E13: PC | F13: 0
... A748: 12000921 | B748: EXPOSITOR QUIMICO METAL SUPERPRO 1X1 | C748: 0805 | D748: 0 | E748: PC | F748: 0
A749: 13000M | B749: ESFREBOM LUVA MULTIUSO M | C749: 0805 | D749: 0 | E749: PC | F749: 0
A750: 13002M | B750: ESFREBOM LUVA COZINHA M | C750: 0805 | D750: 0 | E750: PC | F750: 0
A751: 9256AZ | B751: LIXEIRA PLASTICA SELETIVA AZ 60L 1X6 | C751: 0805 | D751: 0 | E751: PC | F751: 0
A752: 9356B | B752: LIXEIRA PLAST C/PEDAL BR 36L SUPERPRO1X3 | C752: 0805 | D752: 0 | E752: PC | F752: 0
A753: 9357B | B753: LIXEIRA PLAST C/PEDAL BR 72L SUPERPRO1X3 | C753: 0805 | D753: 0 | E753: PC | F753: 0
A754: 9358/9359R | B754: RODA PARA LIXEIRAS 120/240L SUPERPRO 1x2 | C754: 0805 | D754: 0 | E754: PC | F754: 0
A755: C11051E | B755: DISCO LUSTR. VERMELHO 510MM 1X20 | C755: 0805 | D755: 0 | E755: PC | F755: 0
A756: C900450E | B756: ESCOVAO - 1 X 12 | C756: 0805 | D756: 0 | E756: PC | F756: 0
A757: C9004AM | B757: VASSOURA 40CM S/CABO AMARELA 1x12 | C757: 0805 | D757: 0 | E757: PC | F757: 0
A758: C9021CE | B758: VASSOURA SUPER TUPY C/CABO 1X12 | C758: 0805 | D758: 0 | E758: PC | F758: 0
A759: C9054CE | B759: RODO PLAST. BORRACHA DUPLA 40 CM | C759: 0805 | D759: 0 | E759: PC | F759: 0
A760: C9135P | B760: MINI MOP MICROFIBRA TIRAS 1x12 | C760: 0805 | D760: 0 | E760: PC | F760: 0
... A851: SP9941CA | B851: DISCO LUSTRADOR BRANCO 41CM SUPERPRO1x10 | C851: 0805 | D851: 0 | E851: PC | F851: 0
D852: 6810.001 | E852: KG | F852: 843905.7
D853: 0 | E853: L
D854: 8 | E854: M
D855: 1641175 | E855: PC

Sheet 0806
A1: Material | B1: Texto breve material | C1: Depósito | D1: Utilização livre | E1: UMB | F1: Val.utiliz.livre
A2: 3000400 | B2: LIXEIRA C/PEDAL AMARELA 120 L - 9358AM | C2: 0806 | D2: 0 | E2: PC | F2: 0
A3: 3000401 | B3: LIXEIRA C/PEDAL AMARELA 240 L - 9359AM | C3: 0806 | D3: 0 | E3: PC | F3: 0
A4: 3000402 | B4: LIXEIRA C/PEDAL AZUL 120 L - 9358AZ | C4: 0806 | D4: 0 | E4: PC | F4: 0
A5: 3000403 | B5: LIXEIRA C/PEDAL AZUL 240 L - 9359AZ | C5: 0806 | D5: 0 | E5: PC | F5: 0
A6: 3000404 | B6: LIXEIRA C/PEDAL CINZA 120 L - 9358CZ | C6: 0806 | D6: 0 | E6: PC | F6: 0
A7: 3000405 | B7: LIXEIRA C/PEDAL CINZA 240 L - 9359CZ | C7: 0806 | D7: 0 | E7: PC | F7: 0
A8: 3000406 | B8: LIXEIRA C/PEDAL VERDE 120 L - 9358VD | C8: 0806 | D8: 0 | E8: PC | F8: 0
A9: 3000408 | B9: LIXEIRA C/PEDAL VERMELHA 120 L - 9358VR | C9: 0806 | D9: 0 | E9: PC | F9: 0
A10: 3000409 | B10: LIXEIRA C/PEDAL VERMELHA 240 L - 9359VR | C10: 0806 | D10: 0 | E10: PC | F10: 0
A11: 3000411 | B11: LIXEIRA PLAST C/PEDAL 120L - BRANCA | C11: 0806 | D11: 0 | E11: PC | F11: 0
A12: 3002721 | B12: JUMBO RL TNT BRANCO 35G 50VISC/50POL EC | C12: 0806 | D12: 0 | E12: KG | F12: 0
A13: 3002730 | B13: JUMBO RL TNT AZUL 35G 50VISC/50POL EC | C13: 0806 | D13: 0 | E13: KG | F13: 0
... A512: 4016984 | B512: TABULEIRO SUPERPRO | C512: 0806 | D512: 0 | E512: PC | F512: 0
A513: 9674C | B513: VASSOURA NOVICA PLAST CB VR SUPERPRO1X14 | C513: 0806 | D513: 0 | E513: PC | F513: 0
A514: BT1398 | B514: NOVICA MOP LAVA E SECA PLAST 1x2 | C514: 0806 | D514: 0 | E514: PC | F514: 0
A515: C9135P | B515: MINI MOP MICROFIBRA TIRAS 1x12 | C515: 0806 | D515: 0 | E515: PC | F515: 0
A516: C950010BA | B516: FIBRA LIMP BETTACO 1X20X10 | C516: 0806 | D516: 0 | E516: PC | F516: 0
A517: SP1022BR | B517: FOLHA BR GERAL IND. 101X225 1X120 | C517: 0806 | D517: 0 | E517: PC | F517: 0
A518: SP18200LAN | B518: SACO LIXO PLAST 200L LV SUPERPRO1X4X50 | C518: 0806 | D518: 0 | E518: PC | F518: 0
A519: SP18200MAN | B519: SACO LIXO PLAST 200L MD SUPERPRO1X4X50 | C519: 0806 | D519: 0 | E519: PC | F519: 0
A520: SP18250LAN | B520: SACO LIXO PLAST 250L LV SUPERPRO1X1X50 | C520: 0806 | D520: 0 | E520: PC | F520: 0
A521: SP18250MAN | B521: SACO LIXO PLAST 250L MD SUPERPRO1X1X50 | C521: 0806 | D521: 0 | E521: PC | F521: 0
A522: SP9526FR | B522: FIBRA LIMPEZA PESADA SOLUTION 1X10X12​ | C522: 0806 | D522: 0 | E522: PC | F522: 0
A523: SP9944CA | B523: DISCO LUSTRADOR BRANCO 44CM SUPERPRO1x10 | C523: 0806 | D523: 0 | E523: PC | F523: 0
D524: 378.923 | E524: KG | F524: 86426.59
D525: 0 | E525: M
D526: 421002 | E526: PC
